Workbook

Sheet NONO
A2: Nono
B3: Number of units
C4: MW | D4: WE | E4: MW | F4: WE | G4: MW | H4: WE | I4: MW | J4: WE | K4: MW | L4: WE | M4: MW | N4: WE | O4: MW | P4: WE | Q4: MW | R4: WE | S4: MW | T4: WE | U4: MW | V4: WE | W4: MW | X4: WE | Y4: MW | Z4: WE
C5: Jan | E5: Feb | G5: Mar | I5: Apr | K5: May | M5: June | O5: July | Q5: August | S5: September | U5: October | W5: November | Y5: December
A6: Average Occupancy | C6: =C22 -> 0.58548387 | E6: =E22 -> 0.65714286 | G6: =G22 -> 0.74354839 | I6: =I22 -> 0.82 | K6: =K22 -> 0.8283871 | M6: =M22 -> 0.801 | O6: =O22 -> 0.85032258 | Q6: =Q22 -> 0.86451613 | S6: =S22 -> 0.835 | U6: =U22 -> 0.77709677 | W6: =W22 -> 0.68333333 | Y6: =Y22 -> 0.68
A7: Average Occupancy per Midweek and weekend (or special dates and holidays) | C7: 0.55 | D7: 0.65 | E7: 0.62 | F7: 0.75 | G7: 0.7 | H7: 0.85 | I7: 0.78 | J7: 0.88 | K7: 0.8 | L7: 0.88 | M7: 0.78 | N7: 0.85 | O7: 0.83 | P7: 0.9 | Q7: 0.85 | R7: 0.9 | S7: 0.82 | T7: 0.87 | U7: 0.75 | V7: 0.82 | W7: 0.65 | X7: 0.75 | Y7: 0.6 | Z7: 0.8
A8: Number of days per midweek/weekend Price | C8: 20 | D8: 11 | E8: 20 | F8: 8 | G8: 22 | H8: 9 | I8: 18 | J8: 12 | K8: 20 | L8: 11 | M8: 21 | N8: 9 | O8: 22 | P8: 9 | Q8: 22 | R8: 9 | S8: 21 | T8: 9 | U8: 19 | V8: 12 | W8: 20 | X8: 10 | Y8: 18 | Z8: 12
A9: Studio | B9: 22 | C9: 80 | D9: 100 | E9: 85 | F9: 110 | G9: 110 | H9: 135 | I9: 125 | J9: 150 | K9: 125 | L9: 150 | M9: 120 | N9: 140 | O9: 125 | P9: 145 | Q9: 150 | R9: 160 | S9: 130 | T9: 150 | U9: 120 | V9: 145 | W9: 105 | X9: 125 | Y9: 85 | Z9: 140
A10: Studio French Balcony | B10: 13 | C10: =C9*1.05 -> 84 | D10: =D9*1.15 -> 115 | E10: =E9*1.05 -> 89.25 | F10: =F9*1.15 -> 126.5 | G10: =G9*1.05 -> 115.5 | H10: =H9*1.15 -> 155.25 | I10: =I9*1.05 -> 131.25 | J10: =J9*1.15 -> 172.5 | K10: =K9*1.05 -> 131.25 | L10: =L9*1.15 -> 172.5 | M10: =M9*1.05 -> 126 | N10: =N9*1.15 -> 161 | O10: =O9*1.05 -> 131.25 | P10: =P9*1.15 -> 166.75 | Q10: =Q9*1.05 -> 157.5 | R10: =R9*1.15 -> 184 | S10: =S9*1.05 -> 136.5 | T10: =T9*1.15 -> 172.5 | U10: =U9*1.05 -> 126 | V10: =V9*1.15 -> 166.75 | W10: =W9*1.05 -> 110.25 | X10: =X9*1.15 -> 143.75 | Y10: =Y9*1.05 -> 89.25 | Z10: =Z9*1.15 -> 161
A11: Superior Studio | B11: 2 | C11: =C9*1.15 -> 92 | D11: =D9*1.15 -> 115 | E11: =E9*1.15 -> 97.75 | F11: =F9*1.15 -> 126.5 | G11: =G9*1.15 -> 126.5 | H11: =H9*1.15 -> 155.25 | I11: =I9*1.15 -> 143.75 | J11: =J9*1.15 -> 172.5 | ... Z11: =Z9*1.15 -> 161
A12: Studio with Terrace | B12: 4 | C12: =C9*1.15 -> 92 | D12: =D9*1.15 -> 115 | E12: =E9*1.15 -> 97.75 | F12: =F9*1.15 -> 126.5 | G12: =G9*1.2 -> 132 | H12: =H9*1.2 -> 162 | I12: =I9*1.25 -> 156.25 | J12: =J9*1.25 -> 187.5 | K12: =K9*1.25 -> 156.25 | L12: =L9*1.25 -> 187.5 | M12: =M9*1.25 -> 150 | N12: =N9*1.25 -> 175 | O12: =O9*1.25 -> 156.25 | P12: =P9*1.25 -> 181.25 | ... T12: =T9*1.25 -> 187.5 | U12: =U9*1.2 -> 144 | V12: =V9*1.2 -> 174 | W12: =W9*1.15 -> 120.75 | X12: =X9*1.15 -> 143.75 | Y12: =Y9*1.15 -> 97.75 | Z12: =Z9*1.15 -> 161
A13: Triple Studio | B13: 4 | C13: =C9*1.12 -> 89.6 | D13: =D9*1.12 -> 112 | E13: =E9*1.12 -> 95.2 | F13: =F9*1.12 -> 123.2 | G13: =G9*1.12 -> 123.2 | H13: =H9*1.12 -> 151.2 | I13: =I9*1.12 -> 140 | J13: =J9*1.12 -> 168 | ... Z13: =Z9*1.12 -> 156.8
A14: One Bedroom Apartment | B14: 5 | C14: =C9*1.3 -> 104 | D14: =D9*1.3 -> 130 | E14: =E9*1.3 -> 110.5 | F14: =F9*1.3 -> 143 | G14: =G9*1.3 -> 143 | H14: =H9*1.3 -> 175.5 | I14: =I9*1.3 -> 162.5 | J14: =J9*1.3 -> 195 | ... Z14: =Z9*1.3 -> 182
A15: One Bedroom Terrace | B15: 4 | C15: =C9*1.4 -> 112 | D15: =D9*1.4 -> 140 | E15: =E9*1.4 -> 119 | F15: =F9*1.4 -> 154 | G15: =G9*1.4 -> 154 | H15: =H9*1.4 -> 189 | I15: =I9*1.4 -> 175 | J15: =J9*1.4 -> 210 | ... Z15: =Z9*1.4 -> 196
A16: Two Bedroom Terrace | B16: 2 | C16: =C9*1.65 -> 132 | D16: =D9*1.65 -> 165 | E16: =E9*1.65 -> 140.25 | F16: =F9*1.65 -> 181.5 | G16: =G9*1.65 -> 181.5 | H16: =H9*1.65 -> 222.75 | I16: =I9*1.75 -> 218.75 | J16: =J9*1.75 -> 262.5 | K16: =K9*1.75 -> 218.75 | L16: =L9*1.75 -> 262.5 | M16: =M9*1.75 -> 210 | N16: =N9*1.75 -> 245 | O16: =O9*1.75 -> 218.75 | P16: =P9*1.75 -> 253.75 | ... R16: =R9*1.75 -> 280 | S16: =S9*1.65 -> 214.5 | T16: =T9*1.65 -> 247.5 | U16: =U9*1.65 -> 198 | V16: =V9*1.65 -> 239.25 | W16: =W9*1.65 -> 173.25 | X16: =X9*1.65 -> 206.25 | Y16: =Y9*1.65 -> 140.25 | Z16: =Z9*1.65 -> 231
B17: 56 | C17: =($B9*C9*C8*C7)+($B10*C10*C8*C7)+($B11*C11*C8*C7)+($B12*C12*C8*C7)+($B13*C13*C8*C7)+($B14*C14*C8*C7)+($B15*C15*C8*C7)+($B16+C16+C8*C7) -> 52179.4 | D17: =($B9*D9*D8*D7)+($B10*D10*D8*D7)+($B11*D11*D8*D7)+($B12*D12*D8*D7)+($B13*D13*D8*D7)+($B14*D14*D8*D7)+($B15*D15*D8*D7)+($B16+D16+D8*D7) -> 43381.6 | E17: =($B9*E9*E8*E7)+($B10*E10*E8*E7)+($B11*E11*E8*E7)+($B12*E12*E8*E7)+($B13*E13*E8*E7)+($B14*E14*E8*E7)+($B15*E15*E8*E7)+($B16+E16+E8*E7) -> 62477.67 | F17: =($B9*F9*F8*F7)+($B10*F10*F8*F7)+($B11*F11*F8*F7)+($B12*F12*F8*F7)+($B13*F13*F8*F7)+($B14*F14*F8*F7)+($B15*F15*F8*F7)+($B16+F16+F8*F7) -> 40073.3 | G17: =($B9*G9*G8*G7)+($B10*G10*G8*G7)+($B11*G11*G8*G7)+($B12*G12*G8*G7)+($B13*G13*G8*G7)+($B14*G14*G8*G7)+($B15*G15*G8*G7)+($B16+G16+G8*G7) -> 100703.92 | H17: =($B9*H9*H8*H7)+($B10*H10*H8*H7)+($B11*H11*H8*H7)+($B12*H12*H8*H7)+($B13*H13*H8*H7)+($B14*H14*H8*H7)+($B15*H15*H8*H7)+($B16+H16+H8*H7) -> 62848.033 | I17: =($B9*I9*I8*I7)+($B10*I10*I8*I7)+($B11*I11*I8*I7)+($B12*I12*I8*I7)+($B13*I13*I8*I7)+($B14*I14*I8*I7)+($B15*I15*I8*I7)+($B16+I16+I8*I7) -> 104709.94 | J17: =($B9*J9*J8*J7)+($B10*J10*J8*J7)+($B11*J11*J8*J7)+($B12*J12*J8*J7)+($B13*J13*J8*J7)+($B14*J14*J8*J7)+($B15*J15*J8*J7)+($B16+J16+J8*J7) -> 96629.78 | ... Z17: =($B9*Z9*Z8*Z7)+($B10*Z10*Z8*Z7)+($B11*Z11*Z8*Z7)+($B12*Z12*Z8*Z7)+($B13*Z13*Z8*Z7)+($B14*Z14*Z8*Z7)+($B15*Z15*Z8*Z7)+($B16+Z16+Z8*Z7) -> 81460.52
C19: =C17+D17 -> 95561 | E19: =E17+F17 -> 102550.97 | G19: =G17+H17 -> 163551.95 | I19: =I17+J17 -> 201339.72 | K19: =K17+L17 -> 207896.09 | M19: =M17+N17 -> 182644.13 | O19: =O17+P17 -> 207824.92 | Q19: =Q17+R17 -> 246390.63 | S19: =S17+T17 -> 205199.74 | U19: =U17+V17 -> 188426.52 | W19: =W17+X17 -> 137769.58 | Y19: =Y17+Z17 -> 135894.91
B20: Occupancy Yearly | C20: =(C7*C8+D7*D8) -> 18.15 | E20: =(E7*E8+F7*F8) -> 18.4 | G20: =(G7*G8+H7*H8) -> 23.05 | I20: =(I7*I8+J7*J8) -> 24.6 | K20: =(K7*K8+L7*L8) -> 25.68 | M20: =(M7*M8+N7*N8) -> 24.03 | O20: =(O7*O8+P7*P8) -> 26.36 | Q20: =(Q7*Q8+R7*R8) -> 26.8 | S20: =(S7*S8+T7*T8) -> 25.05 | U20: =(U7*U8+V7*V8) -> 24.09 | W20: =(W7*W8+X7*X8) -> 20.5 | Y20: =(Y7*Y8+Z7*Z8) -> 20.4
C21: =C8+D8 -> 31 | E21: =E8+F8 -> 28 | G21: =G8+H8 -> 31 | I21: =I8+J8 -> 30 | K21: =K8+L8 -> 31 | M21: =M8+N8 -> 30 | O21: =O8+P8 -> 31 | Q21: =Q8+R8 -> 31 | S21: =S8+T8 -> 30 | U21: =U8+V8 -> 31 | W21: =W8+X8 -> 30 | Y21: =Y8+Z8 -> 30
C22: =C20/C21 -> 0.58548387 | E22: =E20/E21 -> 0.65714286 | G22: =G20/G21 -> 0.74354839 | I22: =I20/I21 -> 0.82 | K22: =K20/K21 -> 0.8283871 | M22: =M20/M21 -> 0.801 | O22: =O20/O21 -> 0.85032258 | Q22: =Q20/Q21 -> 0.86451613 | S22: =S20/S21 -> 0.835 | U22: =U20/U21 -> 0.77709677 | W22: =W20/W21 -> 0.68333333 | Y22: =Y20/Y21 -> 0.68
B23: =C22*C21+E22*E21+G22*G21+I22*I21+K22*K21+M22*M21+O22*O21+Q22*Q21+S22*S21+U22*U21+W22*W21+Y22*Y21 -> 277.11 | C23: =B23/365 -> 0.75920548
A24: MONTHLY ADR | C24: =C19/(C21*$B$17*C6) -> 94.019087 | E24: =E19/(E21*$B$17*E6) -> 99.525398 | G24: =G19/(G21*$B$17*G6) -> 126.70588 | I24: =I19/(I21*$B$17*I6) -> 146.15253 | K24: =K19/(K21*$B$17*K6) -> 144.56504 | M24: =M19/(M21*$B$17*M6) -> 135.72627 | O24: =O19/(O21*$B$17*O6) -> 140.78753 | Q24: =Q19/(Q21*$B$17*Q6) -> 164.17286 | S24: =S19/(S21*$B$17*S6) -> 146.27869 | U24: =U19/(U21*$B$17*U6) -> 139.67453 | W24: =W19/(W21*$B$17*W6) -> 120.00834 | Y24: =Y19/(Y21*$B$17*Y6) -> 118.95563
A28: INCOME YEARLY | B28: =SUM(C19:Z19) -> 2075050.2 | D28: Euros | F28: =+B28/1.1 -> 1886409.2
A29: OCC YEARLY | C29: =C23 -> 0.75920548
A30: ADR YEARLY | C30: =AVERAGE(C24:Z24) -> 131.38098
A32: Figures incl VAT | C32: =+C30/1.1 -> 119.43726
C34: 140 | D34: =+(C32/$C$34)-1 -> -0.14687674
C36: 133 | D36: =+(C32/$C$36)-1 -> -0.10197552

Sheet Lease option 1
C4: Inv x Space | H4: Units | I4: Inv. x unit | K4: Total inv .
C6: 35000 | F6: Common areas | H6: 1 | I6: =+C6 -> 35000 | K6: =+C6*H6 -> 35000
C7: 5000 | F7: Studio | H7: 22 | I7: =+C7 -> 5000 | K7: =+C7*H7 -> 110000
C8: 5500 | F8: Studio French Balcony | H8: 13 | I8: =+C8 -> 5500 | K8: =+C8*H8 -> 71500
C9: 6000 | F9: Superior Studio | H9: 2 | I9: =+C9 -> 6000 | K9: =+C9*H9 -> 12000
C10: 7000 | F10: Studio with Terrace | H10: 4 | I10: =+C10 -> 7000 | K10: =+C10*H10 -> 28000
C11: 7000 | F11: Triple Studio | H11: 4 | I11: =+C11 -> 7000 | K11: =+C11*H11 -> 28000
C12: 7000 | F12: One Bedroom Apartment | H12: 5 | I12: =+C12 -> 7000 | K12: =+C12*H12 -> 35000
C13: 7000 | F13: One Bedroom Terrace | H13: 4 | I13: =+C13 -> 7000 | K13: =+C13*H13 -> 28000
C14: 8000 | F14: Two Bedroom Terrace | H14: 2 | I14: =+C14 -> 8000 | K14: =+C14*H14 -> 16000
F16: Total investment | K16: =+SUM(K6:K14) -> 363500
F19: Template | H19: Peña | K19: 140.9 | L19: 154.1 | M19: 169.5 | N19: =+M19*(1+$H$27) -> 174.585 | O19: =+N19*(1+$H$27) -> 179.82255 | P19: =+O19*(1+$H$27) -> 185.21723 | Q19: =+P19*(1+$H$27) -> 190.77374 | R19: =+Q19*(1+$H$27) -> 196.49696 | S19: =+R19*(1+$H$27) -> 202.39186 | T19: =+S19*(1+$H$27) -> 208.46362
H21: Fix min. Lease x apartment | K21: 1300 | L21: 1400 | M21: 1500 | N21: =+M21*(1+SUM($H$27)) -> 1545 | O21: =+N21*(1+SUM($H$27)) -> 1591.35 | P21: =+O21*(1+SUM($H$27)) -> 1639.0905 | Q21: =+P21*(1+SUM($H$27)) -> 1688.2632 | R21: =+Q21*(1+SUM($H$27)) -> 1738.9111 | S21: =+R21*(1+SUM($H$27)) -> 1791.0784 | T21: =+S21*(1+SUM($H$27)) -> 1844.8108
H22: /rev | K22: =+K57/K47 -> 0.38528283 | L22: =+L57/L47 -> 0.37639314 | M22: =+M57/M47 -> 0.37419012 | N22: =+N57/N47 -> 0.36801915 | O22: =+O57/O47 -> 0.36100926 | P22: =+P57/P47 -> 0.35413289 | Q22: =+Q57/Q47 -> 0.34648466 | R22: =+R57/R47 -> 0.3407706 | ... T22: =+T57/T47 -> 0.3279125
H24: Variable lease | K24: 0.37 | L24: 0.38 | M24: 0.4 | N24: 0.41 | O24: 0.41 | P24: 0.365 | Q24: 0.365 | R24: 0.365 | S24: 0.365 | T24: 0.365
F27: IPC | H27: 0.03
F28: GROWTH | H28: 0.02
K32: 2026 | L32: 2027 | M32: 2028 | N32: 2029 | O32: 2030 | P32: 2031 | Q32: 2032 | R32: 2033 | S32: 2034 | T32: 2035
F34: % Average occupancy | K34: 0.76 | L34: 0.8 | M34: 0.82 | N34: 0.82 | O34: 0.82 | P34: 0.82 | Q34: 0.82 | R34: 0.82 | S34: 0.82 | T34: 0.82 | W34: =+AVERAGE(K34:T34) -> 0.812
F35: Number of opened days | K35: 365 | L35: 365 | M35: 366 | N35: 365 | O35: 365 | P35: 365 | Q35: 366 | R35: 365 | S35: 365 | T35: 365
F36: Units | K36: 56 | L36: 56 | M36: 56 | N36: 56 | O36: 56 | P36: 56 | Q36: 56 | R36: 56 | S36: 56 | T36: 56
B37: Asaf Assumption | C37: 119.43726 | F37: ADR | K37: =+($H$38*K38+$H$39*K39+$H$40*K40+$H$41*K41+$H$42*K42+$H$43*K43+$H$44*K44+$H$45*K45)/SUM($H$38:$H$45) -> 138.28827 | L37: =+($H$38*L38+$H$39*L39+$H$40*L40+$H$41*L41+$H$42*L42+$H$43*L43+$H$44*L44+$H$45*L45)/SUM($H$38:$H$45) -> 145.20268 | M37: =+($H$38*M38+$H$39*M39+$H$40*M40+$H$41*M41+$H$42*M42+$H$43*M43+$H$44*M44+$H$45*M45)/SUM($H$38:$H$45) -> 152.46281 | N37: =+($H$38*N38+$H$39*N39+$H$40*N40+$H$41*N41+$H$42*N42+$H$43*N43+$H$44*N44+$H$45*N45)/SUM($H$38:$H$45) -> 160.08595 | O37: =+($H$38*O38+$H$39*O39+$H$40*O40+$H$41*O41+$H$42*O42+$H$43*O43+$H$44*O44+$H$45*O45)/SUM($H$38:$H$45) -> 168.09025 | P37: =+($H$38*P38+$H$39*P39+$H$40*P40+$H$41*P41+$H$42*P42+$H$43*P43+$H$44*P44+$H$45*P45)/SUM($H$38:$H$45) -> 176.49476 | Q37: =+($H$38*Q38+$H$39*Q39+$H$40*Q40+$H$41*Q41+$H$42*Q42+$H$43*Q43+$H$44*Q44+$H$45*Q45)/SUM($H$38:$H$45) -> 185.3195 | R37: =+($H$38*R38+$H$39*R39+$H$40*R40+$H$41*R41+$H$42*R42+$H$43*R43+$H$44*R44+$H$45*R45)/SUM($H$38:$H$45) -> 194.58548 | ... T37: =+($H$38*T38+$H$39*T39+$H$40*T40+$H$41*T41+$H$42*T42+$H$43*T43+$H$44*T44+$H$45*T45)/SUM($H$38:$H$45) -> 214.53049 | W37: =+AVERAGE(K37:T37) -> 173.93749
F38: Studio | H38: 22 | K38: 115 | L38: =+K38*(1+SUM($H$27:$H$28)) -> 120.75 | M38: =+L38*(1+SUM($H$27:$H$28)) -> 126.7875 | N38: =+M38*(1+SUM($H$27:$H$28)) -> 133.12688 | O38: =+N38*(1+SUM($H$27:$H$28)) -> 139.78322 | P38: =+O38*(1+SUM($H$27:$H$28)) -> 146.77238 | Q38: =+P38*(1+SUM($H$27:$H$28)) -> 154.111 | R38: =+Q38*(1+SUM($H$27:$H$28)) -> 161.81655 | S38: =+R38*(1+SUM($H$27:$H$28)) -> 169.90738 | T38: =+S38*(1+SUM($H$27:$H$28)) -> 178.40274
F39: Studio French Balcony | H39: 13 | K39: 135 | L39: =+K39*(1+SUM($H$27:$H$28)) -> 141.75 | M39: =+L39*(1+SUM($H$27:$H$28)) -> 148.8375 | N39: =+M39*(1+SUM($H$27:$H$28)) -> 156.27938 | O39: =+N39*(1+SUM($H$27:$H$28)) -> 164.09334 | P39: =+O39*(1+SUM($H$27:$H$28)) -> 172.29801 | Q39: =+P39*(1+SUM($H$27:$H$28)) -> 180.91291 | R39: =+Q39*(1+SUM($H$27:$H$28)) -> 189.95856 | S39: =+R39*(1+SUM($H$27:$H$28)) -> 199.45648 | T39: =+S39*(1+SUM($H$27:$H$28)) -> 209.42931
F40: Superior Studio | H40: 2 | K40: 135 | L40: =+K40*(1+SUM($H$27:$H$28)) -> 141.75 | M40: =+L40*(1+SUM($H$27:$H$28)) -> 148.8375 | N40: =+M40*(1+SUM($H$27:$H$28)) -> 156.27938 | O40: =+N40*(1+SUM($H$27:$H$28)) -> 164.09334 | P40: =+O40*(1+SUM($H$27:$H$28)) -> 172.29801 | Q40: =+P40*(1+SUM($H$27:$H$28)) -> 180.91291 | R40: =+Q40*(1+SUM($H$27:$H$28)) -> 189.95856 | S40: =+R40*(1+SUM($H$27:$H$28)) -> 199.45648 | T40: =+S40*(1+SUM($H$27:$H$28)) -> 209.42931
F41: Studio with Terrace | H41: 4 | K41: 146.03571 | L41: =+K41*(1+SUM($H$27:$H$28)) -> 153.3375 | M41: =+L41*(1+SUM($H$27:$H$28)) -> 161.00438 | N41: =+M41*(1+SUM($H$27:$H$28)) -> 169.05459 | O41: =+N41*(1+SUM($H$27:$H$28)) -> 177.50732 | P41: =+O41*(1+SUM($H$27:$H$28)) -> 186.38269 | Q41: =+P41*(1+SUM($H$27:$H$28)) -> 195.70182 | R41: =+Q41*(1+SUM($H$27:$H$28)) -> 205.48692 | S41: =+R41*(1+SUM($H$27:$H$28)) -> 215.76126 | T41: =+S41*(1+SUM($H$27:$H$28)) -> 226.54932
F42: Triple Studio | H42: 4 | K42: 140 | L42: =+K42*(1+SUM($H$27:$H$28)) -> 147 | M42: =+L42*(1+SUM($H$27:$H$28)) -> 154.35 | N42: =+M42*(1+SUM($H$27:$H$28)) -> 162.0675 | O42: =+N42*(1+SUM($H$27:$H$28)) -> 170.17087 | P42: =+O42*(1+SUM($H$27:$H$28)) -> 178.67942 | Q42: =+P42*(1+SUM($H$27:$H$28)) -> 187.61339 | R42: =+Q42*(1+SUM($H$27:$H$28)) -> 196.99406 | S42: =+R42*(1+SUM($H$27:$H$28)) -> 206.84376 | T42: =+S42*(1+SUM($H$27:$H$28)) -> 217.18595
F43: One Bedroom Apartment | H43: 5 | K43: 165 | L43: =+K43*(1+SUM($H$27:$H$28)) -> 173.25 | M43: =+L43*(1+SUM($H$27:$H$28)) -> 181.9125 | N43: =+M43*(1+SUM($H$27:$H$28)) -> 191.00813 | O43: =+N43*(1+SUM($H$27:$H$28)) -> 200.55853 | P43: =+O43*(1+SUM($H$27:$H$28)) -> 210.58646 | Q43: =+P43*(1+SUM($H$27:$H$28)) -> 221.11578 | R43: =+Q43*(1+SUM($H$27:$H$28)) -> 232.17157 | S43: =+R43*(1+SUM($H$27:$H$28)) -> 243.78015 | T43: =+S43*(1+SUM($H$27:$H$28)) -> 255.96916
F44: One Bedroom Terrace | H44: 4 | K44: 190 | L44: =+K44*(1+SUM($H$27:$H$28)) -> 199.5 | M44: =+L44*(1+SUM($H$27:$H$28)) -> 209.475 | N44: =+M44*(1+SUM($H$27:$H$28)) -> 219.94875 | O44: =+N44*(1+SUM($H$27:$H$28)) -> 230.94619 | P44: =+O44*(1+SUM($H$27:$H$28)) -> 242.4935 | Q44: =+P44*(1+SUM($H$27:$H$28)) -> 254.61817 | R44: =+Q44*(1+SUM($H$27:$H$28)) -> 267.34908 | S44: =+R44*(1+SUM($H$27:$H$28)) -> 280.71653 | T44: =+S44*(1+SUM($H$27:$H$28)) -> 294.75236
F45: Two Bedroom Terrace | H45: 2 | K45: 230 | L45: =+K45*(1+SUM($H$27:$H$28)) -> 241.5 | M45: =+L45*(1+SUM($H$27:$H$28)) -> 253.575 | N45: =+M45*(1+SUM($H$27:$H$28)) -> 266.25375 | O45: =+N45*(1+SUM($H$27:$H$28)) -> 279.56644 | P45: =+O45*(1+SUM($H$27:$H$28)) -> 293.54476 | Q45: =+P45*(1+SUM($H$27:$H$28)) -> 308.222 | R45: =+Q45*(1+SUM($H$27:$H$28)) -> 323.6331 | S45: =+R45*(1+SUM($H$27:$H$28)) -> 339.81475 | T45: =+S45*(1+SUM($H$27:$H$28)) -> 356.80549
F47: Revenue | K47: =+SUM(K48:K51) -> 2267425.2 | L47: =+SUM(L48:L51) -> 2499514.2 | M47: =+SUM(M48:M51) -> 2693817.8 | N47: =+SUM(N48:N51) -> 2821157.5 | O47: =+SUM(O48:O51) -> 2962215.4 | P47: =+SUM(P48:P51) -> 3110326.2 | Q47: =+SUM(Q48:Q51) -> 3274352.4 | R47: =+SUM(R48:R51) -> 3429134.6 | ... T47: =+SUM(T48:T51) -> 3780620.9 | W47: =+SUM(K47:T47) -> 30439156
F48: Bed revenue | K48: =+K34*K35*K36*K37 -> 2148225.2 | L48: =+L34*L35*L36*L37 -> 2374354.2 | M48: =+M34*M35*M36*M37 -> 2562399.8 | N48: =+N34*N35*N36*N37 -> 2683168.6 | O48: =+O34*O35*O36*O37 -> 2817327.1 | P48: =+P34*P35*P36*P37 -> 2958193.4 | Q48: =+Q34*Q35*Q36*Q37 -> 3114613 | R48: =+R34*R35*R36*R37 -> 3261408.3 | ... T48: =+T34*T35*T36*T37 -> 3595702.6
F49: F&B Bartola | H49: 9333.3333 | K49: =+H49*12 -> 112000 | L49: =+K49*(1+SUM($H$27:$H$28)) -> 117600 | M49: =+L49*(1+SUM($H$27:$H$28)) -> 123480 | N49: =+M49*(1+SUM($H$27:$H$28)) -> 129654 | O49: =+N49*(1+SUM($H$27:$H$28)) -> 136136.7 | P49: =+O49*(1+SUM($H$27:$H$28)) -> 142943.54 | Q49: =+P49*(1+SUM($H$27:$H$28)) -> 150090.71 | R49: =+Q49*(1+SUM($H$27:$H$28)) -> 157595.25 | S49: =+R49*(1+SUM($H$27:$H$28)) -> 165475.01 | T49: =+S49*(1+SUM($H$27:$H$28)) -> 173748.76
F50: Experiences | H50: 300 | K50: =+H50*12 -> 3600 | L50: =+K50*(1+SUM($H$27:$H$28)) -> 3780 | M50: =+L50*(1+SUM($H$27:$H$28)) -> 3969 | N50: =+M50*(1+SUM($H$27:$H$28)) -> 4167.45 | O50: =+N50*(1+SUM($H$27:$H$28)) -> 4375.8225 | P50: =+O50*(1+SUM($H$27:$H$28)) -> 4594.6136 | Q50: =+P50*(1+SUM($H$27:$H$28)) -> 4824.3443 | R50: =+Q50*(1+SUM($H$27:$H$28)) -> 5065.5615 | S50: =+R50*(1+SUM($H$27:$H$28)) -> 5318.8396 | T50: =+S50*(1+SUM($H$27:$H$28)) -> 5584.7816
F51: Parking | H51: 300 | K51: =+H51*12 -> 3600 | L51: =+K51*(1+SUM($H$27:$H$28)) -> 3780 | M51: =+L51*(1+SUM($H$27:$H$28)) -> 3969 | N51: =+M51*(1+SUM($H$27:$H$28)) -> 4167.45 | O51: =+N51*(1+SUM($H$27:$H$28)) -> 4375.8225 | P51: =+O51*(1+SUM($H$27:$H$28)) -> 4594.6136 | Q51: =+P51*(1+SUM($H$27:$H$28)) -> 4824.3443 | R51: =+Q51*(1+SUM($H$27:$H$28)) -> 5065.5615 | S51: =+R51*(1+SUM($H$27:$H$28)) -> 5318.8396 | T51: =+S51*(1+SUM($H$27:$H$28)) -> 5584.7816
F53: Grace-Months | H53: =+K16/(K57/12) -> 4.9931319 | K53: =-(K21*56)*H53 -> -363500
F55: Lease to Charming Stay | K55: =+IF(K53<0,MIN(K56:K58),MAX(K56:K58)) -> 510100 | L55: =+IF(L53<0,MIN(L56:L58),MAX(L56:L58)) -> 949815.4 | M55: =+IF(M53<0,MIN(M56:M58),MAX(M56:M58)) -> 1077527.1 | N55: =+IF(N53<0,MIN(N56:N58),MAX(N56:N58)) -> 1156674.6 | O55: =+IF(O53<0,MIN(O56:O58),MAX(O56:O58)) -> 1214508.3 | P55: =+IF(P53<0,MIN(P56:P58),MAX(P56:P58)) -> 1135269.1 | Q55: =+IF(Q53<0,MIN(Q56:Q58),MAX(Q56:Q58)) -> 1195138.6 | R55: =+IF(R53<0,MIN(R56:R58),MAX(R56:R58)) -> 1251634.1 | ... T55: =+IF(T53<0,MIN(T56:T58),MAX(T56:T58)) -> 1379926.6 | W55: =+SUM(K55:T55) -> 11184810
F56: Fix minimum lease | K56: =+K57+K53 -> 510100 | L56: =+L57+L53 -> 940800 | M56: =+M57+M53 -> 1008000 | N56: =+N57+N53 -> 1038240 | O56: =+O57+O53 -> 1069387.2 | P56: =+P57+P53 -> 1101468.8 | Q56: =+Q57+Q53 -> 1134512.9 | R56: =+R57+R53 -> 1168548.3 | ... T56: =+T57+T53 -> 1239712.9
F57: Fix minimum lease | K57: =+K21*K36*12 -> 873600 | L57: =+L21*L36*12 -> 940800 | M57: =+M21*M36*12 -> 1008000 | N57: =+N21*N36*12 -> 1038240 | O57: =+O21*O36*12 -> 1069387.2 | P57: =+P21*P36*12 -> 1101468.8 | Q57: =+Q21*Q36*12 -> 1134512.9 | R57: =+R21*R36*12 -> 1168548.3 | ... T57: =+T21*T36*12 -> 1239712.9
F58: Variable lease | K58: =+K24*K47 -> 838947.33 | L58: =+L24*L47 -> 949815.4 | M58: =+M24*M47 -> 1077527.1 | N58: =+N24*N47 -> 1156674.6 | O58: =+O24*O47 -> 1214508.3 | P58: =+P24*P47 -> 1135269.1 | Q58: =+Q24*Q47 -> 1195138.6 | R58: =+R24*R47 -> 1251634.1 | ... T58: =+T24*T47 -> 1379926.6
...

Sheet Lease option 2
C4: Inv x Space | H4: Units | I4: Inv. x unit | K4: Total inv .
C6: 35000 | F6: Common areas | H6: 1 | I6: =+C6 -> 35000 | K6: =+C6*H6 -> 35000
C7: 5000 | F7: Studio | H7: 22 | I7: =+C7 -> 5000 | K7: =+C7*H7 -> 110000
C8: 5500 | F8: Studio French Balcony | H8: 13 | I8: =+C8 -> 5500 | K8: =+C8*H8 -> 71500
C9: 6000 | F9: Superior Studio | H9: 2 | I9: =+C9 -> 6000 | K9: =+C9*H9 -> 12000
C10: 7000 | F10: Studio with Terrace | H10: 4 | I10: =+C10 -> 7000 | K10: =+C10*H10 -> 28000
C11: 7000 | F11: Triple Studio | H11: 4 | I11: =+C11 -> 7000 | K11: =+C11*H11 -> 28000
C12: 7000 | F12: One Bedroom Apartment | H12: 5 | I12: =+C12 -> 7000 | K12: =+C12*H12 -> 35000
C13: 7000 | F13: One Bedroom Terrace | H13: 4 | I13: =+C13 -> 7000 | K13: =+C13*H13 -> 28000
C14: 8000 | F14: Two Bedroom Terrace | H14: 2 | I14: =+C14 -> 8000 | K14: =+C14*H14 -> 16000
F16: Total investment | K16: =+SUM(K6:K14) -> 363500
F19: Template | H19: Peña | K19: 140.9 | L19: 154.1 | M19: 169.5 | N19: =+M19*(1+$H$27) -> 174.585 | O19: =+N19*(1+$H$27) -> 179.82255 | P19: =+O19*(1+$H$27) -> 185.21723 | Q19: =+P19*(1+$H$27) -> 190.77374 | R19: =+Q19*(1+$H$27) -> 196.49696 | S19: =+R19*(1+$H$27) -> 202.39186 | T19: =+S19*(1+$H$27) -> 208.46362
H21: Fix min. Lease x apartment | K21: 1300 | L21: 1400 | M21: 1500 | N21: =+M21*(1+SUM($H$27)) -> 1545 | O21: =+N21*(1+SUM($H$27)) -> 1591.35 | P21: =+O21*(1+SUM($H$27)) -> 1639.0905 | Q21: =+P21*(1+SUM($H$27)) -> 1688.2632 | R21: =+Q21*(1+SUM($H$27)) -> 1738.9111 | S21: =+R21*(1+SUM($H$27)) -> 1791.0784 | T21: =+S21*(1+SUM($H$27)) -> 1844.8108
H22: /rev | K22: =+K57/K47 -> 0.38528283 | L22: =+L57/L47 -> 0.37639314 | M22: =+M57/M47 -> 0.37419012 | N22: =+N57/N47 -> 0.36801915 | O22: =+O57/O47 -> 0.36100926 | P22: =+P57/P47 -> 0.35413289 | Q22: =+Q57/Q47 -> 0.34648466 | R22: =+R57/R47 -> 0.3407706 | ... T22: =+T57/T47 -> 0.3279125
H24: Variable lease | K24: 0.37 | L24: 0.38 | M24: 0.4 | N24: 0.41 | O24: 0.41 | P24: 0.41 | Q24: 0.41 | R24: 0.41 | S24: 0.41 | T24: 0.41
H25: Variable lease (F&B Bartola) | K25: 0.05 | L25: 0.08 | M25: 0.08 | N25: 0.08 | O25: 0.08 | P25: 0.08 | Q25: 0.08 | R25: 0.08 | S25: 0.08 | T25: 0.08
F27: IPC | H27: 0.03
F28: GROWTH | H28: 0.02
K32: 2026 | L32: 2027 | M32: 2028 | N32: 2029 | O32: 2030 | P32: 2031 | Q32: 2032 | R32: 2033 | S32: 2034 | T32: 2035
F34: % Average occupancy | K34: 0.76 | L34: 0.8 | M34: 0.82 | N34: 0.82 | O34: 0.82 | P34: 0.82 | Q34: 0.82 | R34: 0.82 | S34: 0.82 | T34: 0.82 | W34: =+AVERAGE(K34:T34) -> 0.812
F35: Number of opened days | K35: 365 | L35: 365 | M35: 366 | N35: 365 | O35: 365 | P35: 365 | Q35: 366 | R35: 365 | S35: 365 | T35: 365
F36: Units | K36: 56 | L36: 56 | M36: 56 | N36: 56 | O36: 56 | P36: 56 | Q36: 56 | R36: 56 | S36: 56 | T36: 56
B37: Asaf Assumption | C37: 119.43726 | F37: ADR | K37: =+($H$38*K38+$H$39*K39+$H$40*K40+$H$41*K41+$H$42*K42+$H$43*K43+$H$44*K44+$H$45*K45)/SUM($H$38:$H$45) -> 138.28827 | L37: =+($H$38*L38+$H$39*L39+$H$40*L40+$H$41*L41+$H$42*L42+$H$43*L43+$H$44*L44+$H$45*L45)/SUM($H$38:$H$45) -> 145.20268 | M37: =+($H$38*M38+$H$39*M39+$H$40*M40+$H$41*M41+$H$42*M42+$H$43*M43+$H$44*M44+$H$45*M45)/SUM($H$38:$H$45) -> 152.46281 | N37: =+($H$38*N38+$H$39*N39+$H$40*N40+$H$41*N41+$H$42*N42+$H$43*N43+$H$44*N44+$H$45*N45)/SUM($H$38:$H$45) -> 160.08595 | O37: =+($H$38*O38+$H$39*O39+$H$40*O40+$H$41*O41+$H$42*O42+$H$43*O43+$H$44*O44+$H$45*O45)/SUM($H$38:$H$45) -> 168.09025 | P37: =+($H$38*P38+$H$39*P39+$H$40*P40+$H$41*P41+$H$42*P42+$H$43*P43+$H$44*P44+$H$45*P45)/SUM($H$38:$H$45) -> 176.49476 | Q37: =+($H$38*Q38+$H$39*Q39+$H$40*Q40+$H$41*Q41+$H$42*Q42+$H$43*Q43+$H$44*Q44+$H$45*Q45)/SUM($H$38:$H$45) -> 185.3195 | R37: =+($H$38*R38+$H$39*R39+$H$40*R40+$H$41*R41+$H$42*R42+$H$43*R43+$H$44*R44+$H$45*R45)/SUM($H$38:$H$45) -> 194.58548 | ... T37: =+($H$38*T38+$H$39*T39+$H$40*T40+$H$41*T41+$H$42*T42+$H$43*T43+$H$44*T44+$H$45*T45)/SUM($H$38:$H$45) -> 214.53049 | W37: =+AVERAGE(K37:T37) -> 173.93749
F38: Studio | H38: 22 | K38: 115 | L38: =+K38*(1+SUM($H$27:$H$28)) -> 120.75 | M38: =+L38*(1+SUM($H$27:$H$28)) -> 126.7875 | N38: =+M38*(1+SUM($H$27:$H$28)) -> 133.12688 | O38: =+N38*(1+SUM($H$27:$H$28)) -> 139.78322 | P38: =+O38*(1+SUM($H$27:$H$28)) -> 146.77238 | Q38: =+P38*(1+SUM($H$27:$H$28)) -> 154.111 | R38: =+Q38*(1+SUM($H$27:$H$28)) -> 161.81655 | S38: =+R38*(1+SUM($H$27:$H$28)) -> 169.90738 | T38: =+S38*(1+SUM($H$27:$H$28)) -> 178.40274
F39: Studio French Balcony | H39: 13 | K39: 135 | L39: =+K39*(1+SUM($H$27:$H$28)) -> 141.75 | M39: =+L39*(1+SUM($H$27:$H$28)) -> 148.8375 | N39: =+M39*(1+SUM($H$27:$H$28)) -> 156.27938 | O39: =+N39*(1+SUM($H$27:$H$28)) -> 164.09334 | P39: =+O39*(1+SUM($H$27:$H$28)) -> 172.29801 | Q39: =+P39*(1+SUM($H$27:$H$28)) -> 180.91291 | R39: =+Q39*(1+SUM($H$27:$H$28)) -> 189.95856 | S39: =+R39*(1+SUM($H$27:$H$28)) -> 199.45648 | T39: =+S39*(1+SUM($H$27:$H$28)) -> 209.42931
F40: Superior Studio | H40: 2 | K40: 135 | L40: =+K40*(1+SUM($H$27:$H$28)) -> 141.75 | M40: =+L40*(1+SUM($H$27:$H$28)) -> 148.8375 | N40: =+M40*(1+SUM($H$27:$H$28)) -> 156.27938 | O40: =+N40*(1+SUM($H$27:$H$28)) -> 164.09334 | P40: =+O40*(1+SUM($H$27:$H$28)) -> 172.29801 | Q40: =+P40*(1+SUM($H$27:$H$28)) -> 180.91291 | R40: =+Q40*(1+SUM($H$27:$H$28)) -> 189.95856 | S40: =+R40*(1+SUM($H$27:$H$28)) -> 199.45648 | T40: =+S40*(1+SUM($H$27:$H$28)) -> 209.42931
F41: Studio with Terrace | H41: 4 | K41: 146.03571 | L41: =+K41*(1+SUM($H$27:$H$28)) -> 153.3375 | M41: =+L41*(1+SUM($H$27:$H$28)) -> 161.00438 | N41: =+M41*(1+SUM($H$27:$H$28)) -> 169.05459 | O41: =+N41*(1+SUM($H$27:$H$28)) -> 177.50732 | P41: =+O41*(1+SUM($H$27:$H$28)) -> 186.38269 | Q41: =+P41*(1+SUM($H$27:$H$28)) -> 195.70182 | R41: =+Q41*(1+SUM($H$27:$H$28)) -> 205.48692 | S41: =+R41*(1+SUM($H$27:$H$28)) -> 215.76126 | T41: =+S41*(1+SUM($H$27:$H$28)) -> 226.54932
F42: Triple Studio | H42: 4 | K42: 140 | L42: =+K42*(1+SUM($H$27:$H$28)) -> 147 | M42: =+L42*(1+SUM($H$27:$H$28)) -> 154.35 | N42: =+M42*(1+SUM($H$27:$H$28)) -> 162.0675 | O42: =+N42*(1+SUM($H$27:$H$28)) -> 170.17087 | P42: =+O42*(1+SUM($H$27:$H$28)) -> 178.67942 | Q42: =+P42*(1+SUM($H$27:$H$28)) -> 187.61339 | R42: =+Q42*(1+SUM($H$27:$H$28)) -> 196.99406 | S42: =+R42*(1+SUM($H$27:$H$28)) -> 206.84376 | T42: =+S42*(1+SUM($H$27:$H$28)) -> 217.18595
F43: One Bedroom Apartment | H43: 5 | K43: 165 | L43: =+K43*(1+SUM($H$27:$H$28)) -> 173.25 | M43: =+L43*(1+SUM($H$27:$H$28)) -> 181.9125 | N43: =+M43*(1+SUM($H$27:$H$28)) -> 191.00813 | O43: =+N43*(1+SUM($H$27:$H$28)) -> 200.55853 | P43: =+O43*(1+SUM($H$27:$H$28)) -> 210.58646 | Q43: =+P43*(1+SUM($H$27:$H$28)) -> 221.11578 | R43: =+Q43*(1+SUM($H$27:$H$28)) -> 232.17157 | S43: =+R43*(1+SUM($H$27:$H$28)) -> 243.78015 | T43: =+S43*(1+SUM($H$27:$H$28)) -> 255.96916
F44: One Bedroom Terrace | H44: 4 | K44: 190 | L44: =+K44*(1+SUM($H$27:$H$28)) -> 199.5 | M44: =+L44*(1+SUM($H$27:$H$28)) -> 209.475 | N44: =+M44*(1+SUM($H$27:$H$28)) -> 219.94875 | O44: =+N44*(1+SUM($H$27:$H$28)) -> 230.94619 | P44: =+O44*(1+SUM($H$27:$H$28)) -> 242.4935 | Q44: =+P44*(1+SUM($H$27:$H$28)) -> 254.61817 | R44: =+Q44*(1+SUM($H$27:$H$28)) -> 267.34908 | S44: =+R44*(1+SUM($H$27:$H$28)) -> 280.71653 | T44: =+S44*(1+SUM($H$27:$H$28)) -> 294.75236
F45: Two Bedroom Terrace | H45: 2 | K45: 230 | L45: =+K45*(1+SUM($H$27:$H$28)) -> 241.5 | M45: =+L45*(1+SUM($H$27:$H$28)) -> 253.575 | N45: =+M45*(1+SUM($H$27:$H$28)) -> 266.25375 | O45: =+N45*(1+SUM($H$27:$H$28)) -> 279.56644 | P45: =+O45*(1+SUM($H$27:$H$28)) -> 293.54476 | Q45: =+P45*(1+SUM($H$27:$H$28)) -> 308.222 | R45: =+Q45*(1+SUM($H$27:$H$28)) -> 323.6331 | S45: =+R45*(1+SUM($H$27:$H$28)) -> 339.81475 | T45: =+S45*(1+SUM($H$27:$H$28)) -> 356.80549
F47: Revenue | K47: =+SUM(K48:K51) -> 2267425.2 | L47: =+SUM(L48:L51) -> 2499514.2 | M47: =+SUM(M48:M51) -> 2693817.8 | N47: =+SUM(N48:N51) -> 2821157.5 | O47: =+SUM(O48:O51) -> 2962215.4 | P47: =+SUM(P48:P51) -> 3110326.2 | Q47: =+SUM(Q48:Q51) -> 3274352.4 | R47: =+SUM(R48:R51) -> 3429134.6 | ... T47: =+SUM(T48:T51) -> 3780620.9 | W47: =+SUM(K47:T47) -> 30439156
F48: Bed revenue | K48: =+K34*K35*K36*K37 -> 2148225.2 | L48: =+L34*L35*L36*L37 -> 2374354.2 | M48: =+M34*M35*M36*M37 -> 2562399.8 | N48: =+N34*N35*N36*N37 -> 2683168.6 | O48: =+O34*O35*O36*O37 -> 2817327.1 | P48: =+P34*P35*P36*P37 -> 2958193.4 | Q48: =+Q34*Q35*Q36*Q37 -> 3114613 | R48: =+R34*R35*R36*R37 -> 3261408.3 | ... T48: =+T34*T35*T36*T37 -> 3595702.6
F49: F&B Bartola | H49: 9333.3333 | K49: =+H49*12 -> 112000 | L49: =+K49*(1+SUM($H$27:$H$28)) -> 117600 | M49: =+L49*(1+SUM($H$27:$H$28)) -> 123480 | N49: =+M49*(1+SUM($H$27:$H$28)) -> 129654 | O49: =+N49*(1+SUM($H$27:$H$28)) -> 136136.7 | P49: =+O49*(1+SUM($H$27:$H$28)) -> 142943.54 | Q49: =+P49*(1+SUM($H$27:$H$28)) -> 150090.71 | R49: =+Q49*(1+SUM($H$27:$H$28)) -> 157595.25 | S49: =+R49*(1+SUM($H$27:$H$28)) -> 165475.01 | T49: =+S49*(1+SUM($H$27:$H$28)) -> 173748.76
F50: Experiences | H50: 300 | K50: =+H50*12 -> 3600 | L50: =+K50*(1+SUM($H$27:$H$28)) -> 3780 | M50: =+L50*(1+SUM($H$27:$H$28)) -> 3969 | N50: =+M50*(1+SUM($H$27:$H$28)) -> 4167.45 | O50: =+N50*(1+SUM($H$27:$H$28)) -> 4375.8225 | P50: =+O50*(1+SUM($H$27:$H$28)) -> 4594.6136 | Q50: =+P50*(1+SUM($H$27:$H$28)) -> 4824.3443 | R50: =+Q50*(1+SUM($H$27:$H$28)) -> 5065.5615 | S50: =+R50*(1+SUM($H$27:$H$28)) -> 5318.8396 | T50: =+S50*(1+SUM($H$27:$H$28)) -> 5584.7816
F51: Parking | H51: 300 | K51: =+H51*12 -> 3600 | L51: =+K51*(1+SUM($H$27:$H$28)) -> 3780 | M51: =+L51*(1+SUM($H$27:$H$28)) -> 3969 | N51: =+M51*(1+SUM($H$27:$H$28)) -> 4167.45 | O51: =+N51*(1+SUM($H$27:$H$28)) -> 4375.8225 | P51: =+O51*(1+SUM($H$27:$H$28)) -> 4594.6136 | Q51: =+P51*(1+SUM($H$27:$H$28)) -> 4824.3443 | R51: =+Q51*(1+SUM($H$27:$H$28)) -> 5065.5615 | S51: =+R51*(1+SUM($H$27:$H$28)) -> 5318.8396 | T51: =+S51*(1+SUM($H$27:$H$28)) -> 5584.7816
F53: Grace-Months | H53: =+K16/(K57/12) -> 4.9931319 | K53: =-(K21*56)*H53 -> -363500
F55: Lease to Charming Stay | K55: =+IF(K53<0,MIN(K56:K58),MAX(K56:K58)) -> 510100 | L55: =+IF(L53<0,MIN(L56:L58),MAX(L56:L58)) -> 940800 | M55: =+IF(M53<0,MIN(M56:M58),MAX(M56:M58)) -> 1034309.1 | N55: =+IF(N53<0,MIN(N56:N58),MAX(N56:N58)) -> 1109999.2 | O55: =+IF(O53<0,MIN(O56:O58),MAX(O56:O58)) -> 1165499.1 | P55: =+IF(P53<0,MIN(P56:P58),MAX(P56:P58)) -> 1223774.1 | Q55: =+IF(Q53<0,MIN(Q56:Q58),MAX(Q56:Q58)) -> 1288451.8 | R55: =+IF(R53<0,MIN(R56:R58),MAX(R56:R58)) -> 1349210.9 | ... T55: =+IF(T53<0,MIN(T56:T58),MAX(T56:T58)) -> 1487505 | W55: =+SUM(K55:T55) -> 11526321
F56: Fix minimum lease | K56: =+K57+K53 -> 510100 | L56: =+L57+L53 -> 940800 | M56: =+M57+M53 -> 1008000 | N56: =+N57+N53 -> 1038240 | O56: =+O57+O53 -> 1069387.2 | P56: =+P57+P53 -> 1101468.8 | Q56: =+Q57+Q53 -> 1134512.9 | R56: =+R57+R53 -> 1168548.3 | ... T56: =+T57+T53 -> 1239712.9
F57: Fix minimum lease | K57: =+K21*K36*12 -> 873600 | L57: =+L21*L36*12 -> 940800 | M57: =+M21*M36*12 -> 1008000 | N57: =+N21*N36*12 -> 1038240 | O57: =+O21*O36*12 -> 1069387.2 | P57: =+P21*P36*12 -> 1101468.8 | Q57: =+Q21*Q36*12 -> 1134512.9 | R57: =+R21*R36*12 -> 1168548.3 | ... T57: =+T21*T36*12 -> 1239712.9
...

Sheet FORM
B2: Hospitality form
B4: Building type | C4: TA | E4: FORMULADO | F4: He añadido un if que afecta al lease y a las expenses
B5: Buildable m2 | C5: 483 | E5: FORMULADO
B6: Building status | C6: Partially renovated | E6: FORMULADO | F6: Añadir una fórmula en que tengas que poner x hardcost por m2, x softcost por m2 según esta respuesta. Y en caso de que sea not built el coste de construcción m2 depende de la localización, y habría que preguntarle a chatgpt
B7: Purchase price | C7: 2500000
B8: Exact location | C8: "Based on client"
B9: Construction project | C9: No | E9: PDTE | F9: YES, NO
B11: Bank loan needed | C11: Yes | E11: FORMULADO | F11: YES, NO | Q11: No
B12: Expected loan start date | C12: 46753 | E12: FORMULADO
B14: Operation
B15: Management/Lease | C15: Management | E15: FORMULADO | F15: Management, Lease (poner una explicación clara de cada una)
B18: Exit strategy
B19: Exit year | C19: 2030 | E19: FORMULADO | F19: NO, 2028, 2029, 2030…

Sheet Projections
K3: 2026 | L3: 2027 | M3: 2028 | N3: 2029 | O3: 2030 | P3: 2031 | Q3: 2032 | R3: 2033 | S3: 2034 | T3: 2035
F4: Inversión inicial
F5: Distribución de la compra en años | K5: 0.15 | L5: 0 | M5: 0.85 | N5: 0 | O5: 0 | P5: 0 | Q5: 0 | R5: 0 | S5: 0 | T5: 0
F6: Distribución Hard cost, Soft cost y FF&E | K6: 0 | L6: 0 | M6: 1 | N6: 0 | O6: 0 | P6: 0 | Q6: 0 | R6: 0 | S6: 0 | T6: 0
F12: Inversión inicial | K12: 2026 | L12: 2027 | M12: 2028 | N12: 2029 | O12: 2030 | P12: 2031 | Q12: 2032 | R12: 2033 | S12: 2034 | T12: 2035
F14: Compra | I14: Inv. Total
F15: Precio de compra | I15: =-FORM!C7 -> -2500000 | K15: =+K$5*$I15 -> -375000 | L15: =+L$5*$I15 -> 0 | M15: =+M$5*$I15 -> -2125000 | N15: =+N5*$I15 -> 0 | O15: =+O5*$I15 -> 0 | P15: =+P5*$I15 -> 0 | Q15: =+Q5*$I15 -> 0 | R15: =+R5*$I15 -> 0 | S15: =+S5*$I15 -> 0 | T15: =+T5*$I15 -> 0
B16: 0.012 | F16: ITP | I16: =+$I$15*$B$16 -> -30000 | K16: =+I16 -> -30000 | L16: 0 | M16: 0 | N16: 0 | O16: 0 | P16: 0 | Q16: 0 | R16: 0 | S16: 0 | T16: 0
B17: 0.005 | F17: Abogados | I17: =+$I$15*$B$17 -> -12500 | K17: =+I17 -> -12500 | L17: 0 | M17: 0 | N17: 0 | O17: 0 | P17: 0 | Q17: 0 | R17: 0 | S17: 0 | T17: 0
B18: 0.0023 | F18: Notaría | I18: =+$I$15*$B$18 -> -5750 | K18: =+I18 -> -5750 | L18: 0 | M18: 0 | N18: 0 | O18: 0 | P18: 0 | Q18: 0 | R18: 0 | S18: 0 | T18: 0
B20: sqm | C20: €/sqm
F21: Desarrollo | G21: sqm | H21: €/sqm | I21: Inv. Total
B22: =+FORM!C5 -> 483 | C22: =-IF(FORM!C6="Renovated", 0, IF(FORM!C6="Partially renovated",0.5 * IFERROR(VLOOKUP(IFERROR(VLOOKUP(FORM!$C$4,Table1[#All], 2, FALSE), ""), PEM!$A$1:$F$14, 6, FALSE), 0), IF(OR(FORM!C6="Pending to be renovated", FORM!C6="Not built"),IFERROR(VLOOKUP(IFERROR(VLOOKUP(FORM!$C$4,Table1[#All], 2, FALSE),""), PEM!$A$1:$F$14, 6, FALSE), 0), ""))) -> -623.81475 | F22: Hard cost | G22: =+B22 -> 483 | H22: =+C22 -> -623.81475 | I22: =+G22*H22 -> -301302.52 | K22: =+K$6*$I22 -> 0 | L22: =+L$6*$I22 -> 0 | M22: =+M$6*$I22 -> -301302.52 | N22: =+N$6*$I22 -> 0 | O22: =+O$6*$I22 -> 0 | P22: =+P$6*$I22 -> 0 | Q22: =+Q$6*$I22 -> 0 | R22: =+R$6*$I22 -> 0 | S22: =+S$6*$I22 -> 0 | T22: =+T$6*$H22 -> 0
A23: Soft cost | B23: 0.17 | F23: Soft cost | G23: =+G22 -> 483 | H23: =+C22*B23 -> -106.04851 | I23: =+G23*H23 -> -51221.429 | K23: =+K$6*$I23 -> 0 | L23: =+L$6*$I23 -> 0 | M23: =+M$6*$I23 -> -51221.429 | N23: =+N$6*$I23 -> 0 | O23: =+O$6*$I23 -> 0 | P23: =+P$6*$I23 -> 0 | Q23: =+Q$6*$I23 -> 0 | R23: =+R$6*$I23 -> 0 | ... T23: =+T$6*$I23 -> 0
A24: FF&E x apt | B24: -12000 | F24: FF&E | H24: =+K64 -> 10 | I24: =+B24*H24 -> -120000 | K24: =+K$6*$I24 -> 0 | L24: =+L$6*$I24 -> 0 | M24: =+M$6*$I24 -> -120000 | N24: =+N$6*$I24 -> 0 | O24: =+O$6*$I24 -> 0 | P24: =+P$6*$I24 -> 0 | Q24: =+Q$6*$I24 -> 0 | R24: =+R$6*$I24 -> 0 | ... T24: =+T$6*$I24 -> 0
A25: Rooms/Units | B25: =+ROUNDDOWN(_xlfn.IFS( FORM!C4 = "3 star Hotel", -C22 / Sizes!D3,FORM!C4 = "4 star Hotel", -C22 /Sizes!D4,FORM!C4 = "Luxury Hotel", -C22 / Sizes!D5,FORM!C4 = "TA", -C22 /Sizes!D6),0) -> 10
F26: TOTAL | K26: =+SUM(K15:K18)+SUM(K22:K24) -> -423250 | L26: =+SUM(L15:L18)+SUM(L22:L24) -> 0 | M26: =+SUM(M15:M18)+SUM(M22:M24) -> -2597524 | N26: =+SUM(N15:N18)+SUM(N22:N24) -> 0 | O26: =+SUM(O15:O18)+SUM(O22:O24) -> 0 | P26: =+SUM(P15:P18)+SUM(P22:P24) -> 0 | Q26: =+SUM(Q15:Q18)+SUM(Q22:Q24) -> 0 | R26: =+SUM(R15:R18)+SUM(R22:R24) -> 0 | ... T26: =+SUM(T15:T18)+SUM(T22:T24) -> 0
F30: Lease | K30: 2026 | L30: 2027 | M30: 2028 | N30: 2029 | O30: 2030 | P30: 2031 | Q30: 2032 | R30: 2033 | S30: 2034 | T30: 2035
H32: Months operating | K32: 12 | L32: 12 | M32: 12 | N32: 12 | O32: 12 | P32: 12 | Q32: 12 | R32: 12 | S32: 12 | T32: 12
B34: Hostels | C34: 0.3 | K34: =+K35*15 -> 0 | L34: =+L35*15 -> 0 | M34: =+M35*15 -> 0 | N34: =+N35*15 -> 0 | O34: =+O35*15 -> 0 | P34: =+P35*15 -> 0 | Q34: =+Q35*15 -> 0 | R34: =+R35*15 -> 0 | ... T34: =+T35*15 -> 0
B35: TA | C35: 0.4 | H35: Fix min. Lease x apartment | K35: =IF(FORM!$C$15="Lease",+IF(FORM!$C$4="Hostel",Projections!$C$34,Projections!$C$35)*(Projections!K72/Projections!K64/K32),0) -> 0 | L35: =IF(FORM!$C$15="Lease",+IF(FORM!$C$4="Hostel",Projections!$C$34,Projections!$C$35)*(Projections!L72/Projections!L64/L32),0) -> 0 | M35: =IF(FORM!$C$15="Lease",+IF(FORM!$C$4="Hostel",Projections!$C$34,Projections!$C$35)*(Projections!M72/Projections!M64/M32),0) -> 0 | N35: =IF(FORM!$C$15="Lease",+IF(FORM!$C$4="Hostel",Projections!$C$34,Projections!$C$35)*(Projections!N72/Projections!N64/N32),0) -> 0 | O35: =IF(FORM!$C$15="Lease",+IF(FORM!$C$4="Hostel",Projections!$C$34,Projections!$C$35)*(Projections!O72/Projections!O64/O32),0) -> 0 | P35: =IF(FORM!$C$15="Lease",+IF(FORM!$C$4="Hostel",Projections!$C$34,Projections!$C$35)*(Projections!P72/Projections!P64/P32),0) -> 0 | Q35: =IF(FORM!$C$15="Lease",+IF(FORM!$C$4="Hostel",Projections!$C$34,Projections!$C$35)*(Projections!Q72/Projections!Q64/Q32),0) -> 0 | R35: =IF(FORM!$C$15="Lease",+IF(FORM!$C$4="Hostel",Projections!$C$34,Projections!$C$35)*(Projections!R72/Projections!R64/R32),0) -> 0 | ... T35: =IF(FORM!$C$15="Lease",+IF(FORM!$C$4="Hostel",Projections!$C$34,Projections!$C$35)*(Projections!T72/Projections!T64/T32),0) -> 0
H36: /rev | K36: =+IFERROR(K83/K72,"") | L36: =+IFERROR(L83/L72,"") | M36: =+IFERROR(M83/M72,"") | N36: =+IFERROR(N83/N72,"") -> 0 | O36: =+IFERROR(O83/O72,"") -> 0 | P36: =+IFERROR(P83/P72,"") | Q36: =+IFERROR(Q83/Q72,"") | R36: =+IFERROR(R83/R72,"") | ... T36: =+IFERROR(T83/T72,"")
H38: Variable lease | K38: 0 | L38: 0 | M38: 0 | N38: 0 | O38: 0 | P38: 0 | Q38: 0 | R38: 0 | S38: 0 | T38: 0
H39: Variable lease (F&B Bartola) | K39: 0 | L39: 0 | M39: 0 | N39: 0 | O39: 0 | P39: 0 | Q39: 0 | R39: 0 | S39: 0 | T39: 0
B40: IPC | C40: 0.025
B41: GROWTH | C41: 0.005
F46: Detalles básicos de operación
F48: Tipo de operación | G48: =+FORM!C4 -> TA
F49: Año de inicio de operación | G49: =+C61 -> 2029
F50: Management agreement o alquiler | G50: =+FORM!C15 -> Management
F51: Número de unidades | G51: =+B25 -> 10
I57: Occupanct | K57: 0 | L57: 0 | M57: 0 | N57: 0.8 | O57: 0.85378082 | P57: 0.85378082 | Q57: 0.85378082 | R57: 0.85378082 | S57: 0.85378082 | T57: 0.85378082
B60: Ops start date | C60: 47119 | F60: P&L | K60: 2026 | L60: 2027 | M60: 2028 | N60: 2029 | O60: 2030 | P60: 2031 | Q60: 2032 | R60: 2033 | S60: 2034 | T60: 2035
B61: Ops start year | C61: =+YEAR(C60) -> 2029
F62: % Average occupancy | K62: =+K57 -> 0 | L62: =+L57 -> 0 | M62: =+M57 -> 0 | N62: =+N57 -> 0.8 | O62: =+O57 -> 0.85378082 | P62: =+P57 -> 0.85378082 | Q62: =+Q57 -> 0.85378082 | R62: =+R57 -> 0.85378082 | ... T62: =+T57 -> 0.85378082 | W62: =+AVERAGE(K57:T57) -> 0.59226849 | X62: Pendiente de link Occ%
F63: Number of opened days | K63: =+IF(K$60<$C$61,0,IF(K60=$C$61,DATE($C$61,12,31)-$C$60+1,DATE(K60,12,31)-DATE(K60,1,1)+1)) -> 0 | L63: =+IF(L$60<$C$61,0,IF(L60=$C$61,DATE($C$61,12,31)-$C$60+1,DATE(L60,12,31)-DATE(L60,1,1)+1)) -> 0 | M63: =+IF(M$60<$C$61,0,IF(M60=$C$61,DATE($C$61,12,31)-$C$60+1,DATE(M60,12,31)-DATE(M60,1,1)+1)) -> 0 | N63: =+IF(N$60<$C$61,0,IF(N60=$C$61,DATE($C$61,12,31)-$C$60+1,DATE(N60,12,31)-DATE(N60,1,1)+1)) -> 365 | O63: =+IF(O$60<$C$61,0,IF(O60=$C$61,DATE($C$61,12,31)-$C$60+1,DATE(O60,12,31)-DATE(O60,1,1)+1)) -> 365 | P63: =+IF(P$60<$C$61,0,IF(P60=$C$61,DATE($C$61,12,31)-$C$60+1,DATE(P60,12,31)-DATE(P60,1,1)+1)) -> 365 | Q63: =+IF(Q$60<$C$61,0,IF(Q60=$C$61,DATE($C$61,12,31)-$C$60+1,DATE(Q60,12,31)-DATE(Q60,1,1)+1)) -> 366 | R63: =+IF(R$60<$C$61,0,IF(R60=$C$61,DATE($C$61,12,31)-$C$60+1,DATE(R60,12,31)-DATE(R60,1,1)+1)) -> 365 | ... T63: =+IF(T$60<$C$61,0,IF(T60=$C$61,DATE($C$61,12,31)-$C$60+1,DATE(T60,12,31)-DATE(T60,1,1)+1)) -> 365
B64: To get it from Chat GPT | F64: Units | K64: =+$B$25 -> 10 | L64: =+$B$25 -> 10 | M64: =+$B$25 -> 10 | N64: =+$B$25 -> 10 | O64: =+$B$25 -> 10 | P64: =+$B$25 -> 10 | Q64: =+$B$25 -> 10 | R64: =+$B$25 -> 10 | ... T64: =+$B$25 -> 10
B65: First year ADR | F65: ADR | H65: Units | K65: =+($H$66*K66+$H$69*K69+$H$68*K68+$H$67*K67)/SUM($H$66:$H$69) -> 155 | L65: =+($H$66*L66+$H$69*L69+$H$68*L68+$H$67*L67)/SUM($H$66:$H$69) -> 159.65 | M65: =+($H$66*M66+$H$69*M69+$H$68*M68+$H$67*M67)/SUM($H$66:$H$69) -> 164.4395 | N65: =+($H$66*N66+$H$69*N69+$H$68*N68+$H$67*N67)/SUM($H$66:$H$69) -> 169.37269 | O65: =+($H$66*O66+$H$69*O69+$H$68*O68+$H$67*O67)/SUM($H$66:$H$69) -> 174.45387 | P65: =+($H$66*P66+$H$69*P69+$H$68*P68+$H$67*P67)/SUM($H$66:$H$69) -> 179.68748 | Q65: =+($H$66*Q66+$H$69*Q69+$H$68*Q68+$H$67*Q67)/SUM($H$66:$H$69) -> 185.07811 | R65: =+($H$66*R66+$H$69*R69+$H$68*R68+$H$67*R67)/SUM($H$66:$H$69) -> 190.63045 | ... T65: =+($H$66*T66+$H$69*T69+$H$68*T68+$H$67*T67)/SUM($H$66:$H$69) -> 202.23984 | W65: =+AVERAGE(K65:T65) -> 177.69013
B66: Room type 1 | C66: 155 | F66: =+B66 -> Room type 1 | H66: =+K64 -> 10 | K66: =+C66 -> 155 | L66: =+K66*(1+SUM($C$40:$C$41)) -> 159.65 | M66: =+L66*(1+SUM($C$40:$C$41)) -> 164.4395 | N66: =+M66*(1+SUM($C$40:$C$41)) -> 169.37269 | O66: =+N66*(1+SUM($C$40:$C$41)) -> 174.45387 | P66: =+O66*(1+SUM($C$40:$C$41)) -> 179.68748 | Q66: =+P66*(1+SUM($C$40:$C$41)) -> 185.07811 | R66: =+Q66*(1+SUM($C$40:$C$41)) -> 190.63045 | S66: =+R66*(1+SUM($C$40:$C$41)) -> 196.34936 | T66: =+S66*(1+SUM($C$40:$C$41)) -> 202.23984
B67: Room type 2 | C67: 0 | F67: =+B67 -> Room type 2 | H67: 0 | K67: =+C67 -> 0 | L67: =+K67*(1+SUM($C$40:$C$41)) -> 0 | M67: =+L67*(1+SUM($C$40:$C$41)) -> 0 | N67: =+M67*(1+SUM($C$40:$C$41)) -> 0 | O67: =+N67*(1+SUM($C$40:$C$41)) -> 0 | P67: =+O67*(1+SUM($C$40:$C$41)) -> 0 | Q67: =+P67*(1+SUM($C$40:$C$41)) -> 0 | R67: =+Q67*(1+SUM($C$40:$C$41)) -> 0 | S67: =+R67*(1+SUM($C$40:$C$41)) -> 0 | T67: =+S67*(1+SUM($C$40:$C$41)) -> 0
...

Sheet PEM
A1: Tipo de construcción | B1: PEM €/m² (calidad media) | C1: PEM €/m² (calidad baja -20%) | D1: PEM €/m² (calidad alta +50%) | E1: PEC €/m² (media ×1.2) | F1: Coste total estimado €/m² (media ×1.35)
A2: Vivienda unifamiliar adosada | B2: 1069.12 | C2: 855.296 | D2: 1603.68 | E2: 1282.944 | F2: 1443.312
A3: Vivienda unifamiliar aislada | B3: 1299.39 | C3: 1039.512 | D3: 1949.085 | E3: 1559.268 | F3: 1754.1765
A4: Vivienda plurifamiliar medianera | B4: 924.17 | C4: 739.336 | D4: 1386.255 | E4: 1109.004 | F4: 1247.6295
A5: Vivienda plurifamiliar aislada | B5: 990.99 | C5: 792.792 | D5: 1486.485 | E5: 1189.188 | F5: 1337.8365
A6: Hotel 5 estrellas | B6: 2379.82 | C6: 1903.856 | D6: 3569.73 | E6: 2855.784 | F6: 3212.757
A7: Hotel 4 estrellas | B7: 1975.82 | C7: 1580.656 | D7: 2963.73 | E7: 2370.984 | F7: 2667.357
A8: Hotel 3 estrellas | B8: 1570.78 | C8: 1256.624 | D8: 2356.17 | E8: 1884.936 | F8: 2120.553
A9: Hotel 2 estrellas | B9: 1428.92 | C9: 1143.136 | D9: 2143.38 | E9: 1714.704 | F9: 1929.042
A10: Hotel 1 estrella | B10: 1287.06 | C10: 1029.648 | D10: 1930.59 | E10: 1544.472 | F10: 1737.531
A11: Pensiones, hostales, albergues | B11: 1092.76 | C11: 874.208 | D11: 1639.14 | E11: 1311.312 | F11: 1475.226
A12: Local comercial con acabados | B12: 1135.94 | C12: 908.752 | D12: 1703.91 | E12: 1363.128 | F12: 1533.519
A13: Oficina equipada edificio exclusivo | B13: 1298.36 | C13: 1038.688 | D13: 1947.54 | E13: 1558.032 | F13: 1752.786
A14: Restaurante | B14: 1428.92 | C14: 1143.136 | D14: 2143.38 | E14: 1714.704 | F14: 1929.042
A17: A | B17: B
A18: Tipo personalizado | B18: Tipo oficial COA
A19: Hostel | B19: Pensiones, hostales, albergues
A20: TA | B20: Vivienda plurifamiliar medianera
A21: 3 star Hotel | B21: Hotel 3 estrellas
A22: 4 star Hotel | B22: Hotel 4 estrellas
A23: Luxury Hotel | B23: Hotel 5 estrellas

Sheet Especerías - Expenses
H2: Months operating | K2: 12 | L2: 12 | M2: 12 | N2: 12 | O2: 12 | P2: 12 | Q2: 12 | R2: 12 | S2: 12 | T2: 12
F4: IPC | H4: 0.025
F5: GROWTH | H5: 0.02
K9: 2026 | L9: 2027 | M9: 2028 | N9: 2029 | O9: 2030 | P9: 2031 | Q9: 2032 | R9: 2033 | S9: 2034 | T9: 2035
F11: % Average occupancy | K11: =+Projections!K57 -> 0 | L11: =+Projections!L57 -> 0 | M11: =+Projections!M57 -> 0 | N11: =+Projections!N57 -> 0.8 | O11: =+Projections!O57 -> 0.85378082 | P11: =+Projections!P57 -> 0.85378082 | Q11: =+Projections!Q57 -> 0.85378082 | R11: =+Projections!R57 -> 0.85378082 | ... T11: =+Projections!T57 -> 0.85378082 | W11: =+AVERAGE(K11:T11) -> 0.59226849
F12: Number of opened days | K12: 365 | L12: 365 | M12: 366 | N12: 365 | O12: 365 | P12: 365 | Q12: 366 | R12: 365 | S12: 365 | T12: 365
F13: Units | K13: =+Projections!K64 -> 10 | L13: =+Projections!L64 -> 10 | M13: =+Projections!M64 -> 10 | N13: =+Projections!N64 -> 10 | O13: =+Projections!O64 -> 10 | P13: =+Projections!P64 -> 10 | Q13: =+Projections!Q64 -> 10 | R13: =+Projections!R64 -> 10 | ... T13: =+Projections!T64 -> 10
F14: ADR | K14: =+Projections!K65 -> 155 | L14: =+Projections!L65 -> 159.65 | M14: =+Projections!M65 -> 164.4395 | N14: =+Projections!N65 -> 169.37269 | O14: =+Projections!O65 -> 174.45387 | P14: =+Projections!P65 -> 179.68748 | Q14: =+Projections!Q65 -> 185.07811 | R14: =+Projections!R65 -> 190.63045 | ... T14: =+Projections!T65 -> 202.23984 | W14: =+AVERAGE(K14:T14) -> 177.69013
F15: Revenue | H15: Monthly | K15: =+SUM(K16:K19) -> 0 | L15: =+SUM(L16:L19) -> 0 | M15: =+SUM(M16:M19) -> 0 | N15: =+SUM(N16:N19) -> 519296.65 | O15: =+SUM(O16:O19) -> 570833.11 | P15: =+SUM(P16:P19) -> 587958.1 | Q15: =+SUM(Q16:Q19) -> 607256.02 | R15: =+SUM(R16:R19) -> 623764.75 | ... T15: =+SUM(T16:T19) -> 661752.03 | W15: =+SUM(K15:T15) -> 4213338.4
F16: Bed revenue | K16: =+K11*K12*K13*K14 -> 0 | L16: =+L11*L12*L13*L14 -> 0 | M16: =+M11*M12*M13*M14 -> 0 | N16: =+N11*N12*N13*N14 -> 494568.24 | O16: =+O11*O12*O13*O14 -> 543650.58 | P16: =+P11*P12*P13*P14 -> 559960.1 | Q16: =+Q11*Q12*Q13*Q14 -> 578339.06 | R16: =+R11*R12*R13*R14 -> 594061.67 | ... T16: =+T11*T12*T13*T14 -> 630240.02
F17: F&B | H17: =+Projections!C73 -> 0.05 | I17: x Apt | K17: =+K11*K12*K13*K14*$H$17 -> 0 | L17: =+L11*L12*L13*L14*$H$17 -> 0 | M17: =+M11*M12*M13*M14*$H$17 -> 0 | N17: =+N11*N12*N13*N14*$H$17 -> 24728.412 | O17: =+O11*O12*O13*O14*$H$17 -> 27182.529 | P17: =+P11*P12*P13*P14*$H$17 -> 27998.005 | Q17: =+Q11*Q12*Q13*Q14*$H$17 -> 28916.953 | R17: =+R11*R12*R13*R14*$H$17 -> 29703.083 | ... T17: =+T11*T12*T13*T14*$H$17 -> 31512.001
F18: Experiences | H18: 0 | K18: =+H18*12 -> 0 | L18: =+K18*(1+SUM($H$4:$H$5)) -> 0 | M18: =+L18*(1+SUM($H$4:$H$5)) -> 0 | N18: =+M18*(1+SUM($H$4:$H$5)) -> 0 | O18: =+N18*(1+SUM($H$4:$H$5)) -> 0 | P18: =+O18*(1+SUM($H$4:$H$5)) -> 0 | Q18: =+P18*(1+SUM($H$4:$H$5)) -> 0 | R18: =+Q18*(1+SUM($H$4:$H$5)) -> 0 | S18: =+R18*(1+SUM($H$4:$H$5)) -> 0 | T18: =+S18*(1+SUM($H$4:$H$5)) -> 0
F19: Parking | H19: 0 | K19: =+H19*12 -> 0 | L19: =+K19*(1+SUM($H$4:$H$5)) -> 0 | M19: =+L19*(1+SUM($H$4:$H$5)) -> 0 | N19: =+M19*(1+SUM($H$4:$H$5)) -> 0 | O19: =+N19*(1+SUM($H$4:$H$5)) -> 0 | P19: =+O19*(1+SUM($H$4:$H$5)) -> 0 | Q19: =+P19*(1+SUM($H$4:$H$5)) -> 0 | R19: =+Q19*(1+SUM($H$4:$H$5)) -> 0 | S19: =+R19*(1+SUM($H$4:$H$5)) -> 0 | T19: =+S19*(1+SUM($H$4:$H$5)) -> 0
F24: Total nights sold | H24: =+K13*K12*K11 -> 0
E26: Employees | F26: Expenses | H26: Monthly | K26: =+K27+K28+K32+K36+K41+K52+K56+K57+K59+K60+K63 -> 376002.29 | L26: =+L27+L28+L32+L36+L41+L52+L56+L57+L59+L60+L63 -> 385402.34 | M26: =+M27+M28+M32+M36+M41+M52+M56+M57+M59+M60+M63 -> 395037.4 | N26: =+N27+N28+N32+N36+N41+N52+N56+N57+N59+N60+N63 -> 404913.34 | O26: =+O27+O28+O32+O36+O41+O52+O56+O57+O59+O60+O63 -> 415036.17 | P26: =+P27+P28+P32+P36+P41+P52+P56+P57+P59+P60+P63 -> 425412.07 | Q26: =+Q27+Q28+Q32+Q36+Q41+Q52+Q56+Q57+Q59+Q60+Q63 -> 436047.38 | R26: =+R27+R28+R32+R36+R41+R52+R56+R57+R59+R60+R63 -> 446948.56 | ... T26: =+T27+T28+T32+T36+T41+T52+T56+T57+T59+T60+T63 -> 469575.33 | W26: =+SUM(K26:T26) -> 4212497.2 | X26: =+K26/K15 -> #DIV/0!
C27: =1/84 -> 0.011904762 | E27: 1 | F27: Asset Manager | H27: 2750 | I27: N | K27: =+$H27*$E27*K2 -> 33000 | L27: =+K27*(1+$H$4) -> 33825 | M27: =+L27*(1+$H$4) -> 34670.625 | N27: =+M27*(1+$H$4) -> 35537.391 | O27: =+N27*(1+$H$4) -> 36425.825 | P27: =+O27*(1+$H$4) -> 37336.471 | Q27: =+P27*(1+$H$4) -> 38269.883 | R27: =+Q27*(1+$H$4) -> 39226.63 | S27: =+R27*(1+$H$4) -> 40207.296 | T27: =+S27*(1+$H$4) -> 41212.478
A28: N | B28: NOMINAL | F28: Cleaning | K28: =+SUM(K29:K31) -> 75342.857 | L28: =+K28*(1+$H$4) -> 77226.429 | M28: =+L28*(1+$H$4) -> 79157.089 | N28: =+M28*(1+$H$4) -> 81136.017 | O28: =+N28*(1+$H$4) -> 83164.417 | P28: =+O28*(1+$H$4) -> 85243.527 | Q28: =+P28*(1+$H$4) -> 87374.616 | R28: =+Q28*(1+$H$4) -> 89558.981 | S28: =+R28*(1+$H$4) -> 91797.955 | T28: =+S28*(1+$H$4) -> 94092.904
A29: W | B29: WEIGHTS/REV | C29: =1/84 -> 0.011904762 | E29: 1 | F29: Housekeeper Payroll | H29: 2350 | I29: N | K29: =+$H29*$E29*K2 -> 28200 | L29: =+K29*(1+$H$4) -> 28905 | M29: =+L29*(1+$H$4) -> 29627.625 | N29: =+M29*(1+$H$4) -> 30368.316 | O29: =+N29*(1+$H$4) -> 31127.524 | P29: =+O29*(1+$H$4) -> 31905.712 | Q29: =+P29*(1+$H$4) -> 32703.354 | R29: =+Q29*(1+$H$4) -> 33520.938 | S29: =+R29*(1+$H$4) -> 34358.962 | T29: =+S29*(1+$H$4) -> 35217.936
A30: R | B30: RATIOS | C30: 0.19642857 | E30: =+C30*K13 -> 1.9642857 | F30: Cleaning cost payroll | H30: 2000 | I30: N | K30: =+$H30*$E30*K2 -> 47142.857 | L30: =+K30*(1+$H$4) -> 48321.429 | M30: =+L30*(1+$H$4) -> 49529.464 | N30: =+M30*(1+$H$4) -> 50767.701 | O30: =+N30*(1+$H$4) -> 52036.893 | P30: =+O30*(1+$H$4) -> 53337.816 | Q30: =+P30*(1+$H$4) -> 54671.261 | R30: =+Q30*(1+$H$4) -> 56038.043 | S30: =+R30*(1+$H$4) -> 57438.994 | T30: =+S30*(1+$H$4) -> 58874.969
F31: Other cleaning + products | H31: 1.2 | I31: R | K31: =+$H31*$H$24 -> 0 | L31: =+K31*(1+$H$4) -> 0 | M31: =+L31*(1+$H$4) -> 0 | N31: =+M31*(1+$H$4) -> 0 | O31: =+N31*(1+$H$4) -> 0 | P31: =+O31*(1+$H$4) -> 0 | Q31: =+P31*(1+$H$4) -> 0 | R31: =+Q31*(1+$H$4) -> 0 | S31: =+R31*(1+$H$4) -> 0 | T31: =+S31*(1+$H$4) -> 0
F32: Maintenance | K32: =+SUM(K33:K35) -> 58800 | L32: =+K32*(1+$H$4) -> 60270 | M32: =+L32*(1+$H$4) -> 61776.75 | N32: =+M32*(1+$H$4) -> 63321.169 | O32: =+N32*(1+$H$4) -> 64904.198 | P32: =+O32*(1+$H$4) -> 66526.803 | Q32: =+P32*(1+$H$4) -> 68189.973 | R32: =+Q32*(1+$H$4) -> 69894.722 | S32: =+R32*(1+$H$4) -> 71642.09 | T32: =+S32*(1+$H$4) -> 73433.143
F33: Elevator maintenance | H33: 500 | I33: N | K33: =+H33*K2 -> 6000 | L33: =+K33*(1+$H$4) -> 6150 | M33: =+L33*(1+$H$4) -> 6303.75 | N33: =+M33*(1+$H$4) -> 6461.3437 | O33: =+N33*(1+$H$4) -> 6622.8773 | P33: =+O33*(1+$H$4) -> 6788.4493 | Q33: =+P33*(1+$H$4) -> 6958.1605 | R33: =+Q33*(1+$H$4) -> 7132.1145 | S33: =+R33*(1+$H$4) -> 7310.4174 | T33: =+S33*(1+$H$4) -> 7493.1778
C34: =1.5/84 -> 0.017857143 | E34: 2 | F34: Maintenance cost payroll | H34: 2200 | I34: N | K34: =+$H34*$E34*K2 -> 52800 | L34: =+K34*(1+$H$4) -> 54120 | M34: =+L34*(1+$H$4) -> 55473 | N34: =+M34*(1+$H$4) -> 56859.825 | O34: =+N34*(1+$H$4) -> 58281.321 | P34: =+O34*(1+$H$4) -> 59738.354 | Q34: =+P34*(1+$H$4) -> 61231.812 | R34: =+Q34*(1+$H$4) -> 62762.608 | S34: =+R34*(1+$H$4) -> 64331.673 | T34: =+S34*(1+$H$4) -> 65939.965
F35: Maintenance expenses | H35: 0.35 | I35: R | K35: =+$H35*$H$24 -> 0 | L35: =+K35*(1+$H$4) -> 0 | M35: =+L35*(1+$H$4) -> 0 | N35: =+M35*(1+$H$4) -> 0 | O35: =+N35*(1+$H$4) -> 0 | P35: =+O35*(1+$H$4) -> 0 | Q35: =+P35*(1+$H$4) -> 0 | R35: =+Q35*(1+$H$4) -> 0 | S35: =+R35*(1+$H$4) -> 0 | T35: =+S35*(1+$H$4) -> 0
F36: Marketing | K36: =+SUM(K37:K40) -> 0 | L36: =+K36*(1+$H$4) -> 0 | M36: =+L36*(1+$H$4) -> 0 | N36: =+M36*(1+$H$4) -> 0 | O36: =+N36*(1+$H$4) -> 0 | P36: =+O36*(1+$H$4) -> 0 | Q36: =+P36*(1+$H$4) -> 0 | R36: =+Q36*(1+$H$4) -> 0 | S36: =+R36*(1+$H$4) -> 0 | T36: =+S36*(1+$H$4) -> 0
F37: Marketing Expenses | H37: 0.025 | I37: W | K37: =+$H37*K$15 -> 0 | L37: =+K37*(1+$H$4) -> 0 | M37: =+L37*(1+$H$4) -> 0 | N37: =+M37*(1+$H$4) -> 0 | O37: =+N37*(1+$H$4) -> 0 | P37: =+O37*(1+$H$4) -> 0 | Q37: =+P37*(1+$H$4) -> 0 | R37: =+Q37*(1+$H$4) -> 0 | S37: =+R37*(1+$H$4) -> 0 | T37: =+S37*(1+$H$4) -> 0
E38: 0 | F38: Experience payroll | H38: 2200 | I38: N | K38: =+$H38*$E38*K2 -> 0 | L38: =+K38*(1+$H$4) -> 0 | M38: =+L38*(1+$H$4) -> 0 | N38: =+M38*(1+$H$4) -> 0 | O38: =+N38*(1+$H$4) -> 0 | P38: =+O38*(1+$H$4) -> 0 | Q38: =+P38*(1+$H$4) -> 0 | R38: =+Q38*(1+$H$4) -> 0 | S38: =+R38*(1+$H$4) -> 0 | T38: =+S38*(1+$H$4) -> 0
F39: Experience expenses | H39: 0.14 | I39: W/Exp. Rev | K39: =+$H39*K$18 -> 0 | L39: =+K39*(1+$H$4) -> 0 | M39: =+L39*(1+$H$4) -> 0 | N39: =+M39*(1+$H$4) -> 0 | O39: =+N39*(1+$H$4) -> 0 | P39: =+O39*(1+$H$4) -> 0 | Q39: =+P39*(1+$H$4) -> 0 | R39: =+Q39*(1+$H$4) -> 0 | S39: =+R39*(1+$H$4) -> 0 | T39: =+S39*(1+$H$4) -> 0
F40: Experience insurance | H40: 0 | I40: N | K40: =+H40*K2 -> 0 | L40: =+K40*(1+$H$4) -> 0 | M40: =+L40*(1+$H$4) -> 0 | N40: =+M40*(1+$H$4) -> 0 | O40: =+N40*(1+$H$4) -> 0 | P40: =+O40*(1+$H$4) -> 0 | Q40: =+P40*(1+$H$4) -> 0 | R40: =+Q40*(1+$H$4) -> 0 | S40: =+R40*(1+$H$4) -> 0 | T40: =+S40*(1+$H$4) -> 0
F41: Others | K41: =+SUM(K42:K51) -> 10364.429 | L41: =+K41*(1+$H$4) -> 10623.539 | M41: =+L41*(1+$H$4) -> 10889.128 | N41: =+M41*(1+$H$4) -> 11161.356 | O41: =+N41*(1+$H$4) -> 11440.39 | P41: =+O41*(1+$H$4) -> 11726.4 | Q41: =+P41*(1+$H$4) -> 12019.56 | R41: =+Q41*(1+$H$4) -> 12320.049 | S41: =+R41*(1+$H$4) -> 12628.05 | T41: =+S41*(1+$H$4) -> 12943.751
F42: Amenities | H42: 0.5 | I42: R | K42: =+$H42*$H$24 -> 0 | L42: =+K42*(1+$H$4) -> 0 | M42: =+L42*(1+$H$4) -> 0 | N42: =+M42*(1+$H$4) -> 0 | O42: =+N42*(1+$H$4) -> 0 | P42: =+O42*(1+$H$4) -> 0 | Q42: =+P42*(1+$H$4) -> 0 | R42: =+Q42*(1+$H$4) -> 0 | S42: =+R42*(1+$H$4) -> 0 | T42: =+S42*(1+$H$4) -> 0
F43: Fire System | H43: 65 | I43: N | K43: =+H43*K2 -> 780 | L43: =+K43*(1+$H$4) -> 799.5 | M43: =+L43*(1+$H$4) -> 819.4875 | N43: =+M43*(1+$H$4) -> 839.97469 | O43: =+N43*(1+$H$4) -> 860.97405 | P43: =+O43*(1+$H$4) -> 882.49841 | Q43: =+P43*(1+$H$4) -> 904.56087 | R43: =+Q43*(1+$H$4) -> 927.17489 | S43: =+R43*(1+$H$4) -> 950.35426 | T43: =+S43*(1+$H$4) -> 974.11312
C44: 22.321429 | F44: Insurances | H44: =+C44*K13 -> 223.21429 | I44: N | K44: =+H44*K2 -> 2678.5714 | L44: =+K44*(1+$H$4) -> 2745.5357 | M44: =+L44*(1+$H$4) -> 2814.1741 | N44: =+M44*(1+$H$4) -> 2884.5285 | O44: =+N44*(1+$H$4) -> 2956.6417 | P44: =+O44*(1+$H$4) -> 3030.5577 | Q44: =+P44*(1+$H$4) -> 3106.3217 | R44: =+Q44*(1+$H$4) -> 3183.9797 | S44: =+R44*(1+$H$4) -> 3263.5792 | T44: =+S44*(1+$H$4) -> 3345.1687
F45: Taxes | H45: 0 | I45: N | K45: =+H45*K2 -> 0 | L45: =+K45*(1+$H$4) -> 0 | M45: =+L45*(1+$H$4) -> 0 | N45: =+M45*(1+$H$4) -> 0 | O45: =+N45*(1+$H$4) -> 0 | P45: =+O45*(1+$H$4) -> 0 | Q45: =+P45*(1+$H$4) -> 0 | R45: =+Q45*(1+$H$4) -> 0 | S45: =+R45*(1+$H$4) -> 0 | T45: =+S45*(1+$H$4) -> 0
C46: 5.952381 | F46: Duve | H46: =+C46*K13 -> 59.52381 | I46: N | K46: =+H46*K2 -> 714.28571 | L46: =+K46*(1+$H$4) -> 732.14286 | M46: =+L46*(1+$H$4) -> 750.44643 | N46: =+M46*(1+$H$4) -> 769.20759 | O46: =+N46*(1+$H$4) -> 788.43778 | P46: =+O46*(1+$H$4) -> 808.14872 | Q46: =+P46*(1+$H$4) -> 828.35244 | R46: =+Q46*(1+$H$4) -> 849.06125 | S46: =+R46*(1+$H$4) -> 870.28778 | T46: =+S46*(1+$H$4) -> 892.04498
C47: 14 | F47: Mews software | H47: =+C47*$K$13 -> 140 | I47: N | K47: =+H47*K2 -> 1680 | L47: =+K47*(1+$H$4) -> 1722 | M47: =+L47*(1+$H$4) -> 1765.05 | N47: =+M47*(1+$H$4) -> 1809.1762 | O47: =+N47*(1+$H$4) -> 1854.4057 | P47: =+O47*(1+$H$4) -> 1900.7658 | Q47: =+P47*(1+$H$4) -> 1948.2849 | R47: =+Q47*(1+$H$4) -> 1996.9921 | S47: =+R47*(1+$H$4) -> 2046.9169 | T47: =+S47*(1+$H$4) -> 2098.0898
F48: Stripe fees | H48: 0.03 | I48: W | K48: =+$H48*K$15 -> 0 | L48: =+K48*(1+$H$4) -> 0 | M48: =+L48*(1+$H$4) -> 0 | N48: =+M48*(1+$H$4) -> 0 | O48: =+N48*(1+$H$4) -> 0 | P48: =+O48*(1+$H$4) -> 0 | Q48: =+P48*(1+$H$4) -> 0 | R48: =+Q48*(1+$H$4) -> 0 | S48: =+R48*(1+$H$4) -> 0 | T48: =+S48*(1+$H$4) -> 0
F49: Bank fees | H49: 0.002 | I49: W | K49: =+$H49*K$15 -> 0 | L49: =+K49*(1+$H$4) -> 0 | M49: =+L49*(1+$H$4) -> 0 | N49: =+M49*(1+$H$4) -> 0 | O49: =+N49*(1+$H$4) -> 0 | P49: =+O49*(1+$H$4) -> 0 | Q49: =+P49*(1+$H$4) -> 0 | R49: =+Q49*(1+$H$4) -> 0 | S49: =+R49*(1+$H$4) -> 0 | T49: =+S49*(1+$H$4) -> 0
C50: 14.5 | F50: Labour consulting | H50: =+C50*(SUM($E$27:$E$66)) -> 187.98214 | I50: N | K50: =+H50*K2 -> 2255.7857 | L50: =+K50*(1+$H$4) -> 2312.1804 | M50: =+L50*(1+$H$4) -> 2369.9849 | N50: =+M50*(1+$H$4) -> 2429.2345 | O50: =+N50*(1+$H$4) -> 2489.9653 | P50: =+O50*(1+$H$4) -> 2552.2145 | Q50: =+P50*(1+$H$4) -> 2616.0198 | R50: =+Q50*(1+$H$4) -> 2681.4203 | S50: =+R50*(1+$H$4) -> 2748.4559 | T50: =+S50*(1+$H$4) -> 2817.1672
F51: Occupational risk prevention | H51: =+H50 -> 187.98214 | I51: N | K51: =+H51*K2 -> 2255.7857 | L51: =+K51*(1+$H$4) -> 2312.1804 | M51: =+L51*(1+$H$4) -> 2369.9849 | N51: =+M51*(1+$H$4) -> 2429.2345 | O51: =+N51*(1+$H$4) -> 2489.9653 | P51: =+O51*(1+$H$4) -> 2552.2145 | Q51: =+P51*(1+$H$4) -> 2616.0198 | R51: =+Q51*(1+$H$4) -> 2681.4203 | S51: =+R51*(1+$H$4) -> 2748.4559 | T51: =+S51*(1+$H$4) -> 2817.1672
...

Sheet Sheet2
B3: Ratios personal
C5: Real | D5: Units
B6: Recepción Hostels | C6: 10.9 | D6: =57+115 -> 172 | E6: =+C6/D6 -> 0.063372093 | F6: x unit in Hostels
B7: Recepción TA | C7: 4 | D7: =11+15+14+15+29 -> 84 | E7: =+C7/D7 -> 0.047619048 | F7: x apt
B8: Cleaners

Sheet Superfícies
D2: sin zonas comunes
B3: Planta | C3: Apartamento | D3: Superficie construida (m²) | E3: Superficie útil (m²)
B4: Planta baja | C4: local comercial | D4: ?? | E4: ??
B5: 1ª planta | C5: A | D5: 49.2 | E5: 40.77
B6: 1ª planta | C6: B | D6: 59.72 | E6: 47.07
B7: 2ª planta | C7: A | D7: 49.2 | E7: 40.77
B8: 2ª planta | C8: B | D8: 59.72 | E8: 47.07
B9: 3ª planta | C9: A | D9: 49.2 | E9: 40.77
B10: 3ª planta | C10: B | D10: 59.72 | E10: 47.07
B11: Ático | C11: C | D11: 90.4 | E11: 69.27
D12: =SUM(D5:D11) -> 417.16 | E12: =SUM(E5:E11) -> 332.79
B62: Floor | C62: Standard Rooms | D62: Suites | E62: Total Rooms
B63: First Floor | C63: 18 | D63: 0 | E63: 18
B64: Second Floor | C64: 18 | D64: 0 | E64: 18
B65: Third Floor | C65: 14 | D65: 4 | E65: 18
B66: Fourth Floor | C66: 14 | D66: 4 | E66: 18
B67: Penthouse | C67: 0 | D67: 0 | E67: 0
B68: Total | C68: 64 | D68: 8 | E68: 72

Sheet Sizes
A1: Tipo de producto | B1: m2 mínimos por unidad | C1: m2 máximos por unidad | D1: Average m2
A2: Hostel | D2: 11.5
A3: 3 star Hotel | B3: 30 | C3: 35 | D3: =+AVERAGE(B3:C3) -> 32.5
A4: 4 star Hotel | B4: 35 | C4: 45 | D4: =+AVERAGE(B4:C4) -> 40
A5: Luxury Hotel | B5: 45 | C5: 60 | D5: =+AVERAGE(B5:C5) -> 52.5
A6: TA | B6: 50 | C6: 70 | D6: =+AVERAGE(B6:C6) -> 60

Sheet Listings
B2: Building type: | D2: YES/NO
B4: Hostel | D4: Yes
B5: TA | D5: No
B6: 3 star Hotel
B7: 4 star Hotel
B8: Luxury Hotel
B10: Building situation
B12: Renovated
B13: Partially renovated
B14: Pending to be renovated
B15: Not built
B18: Building luxury standards
B20: 1
B21: 2
B22: 3
B23: 4
B24: 5 (5 star hotel level)
B27: Operation
B29: Management
B30: Lease
